Workbook

Sheet 부작 목록
A1: 부작 번호 | B1: 파트 | C1: 부작 제목 | D1: 시작 화 | E1: 끝 화 | F1: 화 수 | G1: 대화 줄 수(근사) | H1: 핵심 내용 | I1: 저장소 해설 폴더
A2: 1 | B2: A 일상 회화 | C2: 식당 수다와 『리처』 토론 | D2: 1 | E2: 7 | F2: =COUNTIF('화 목록'!$B$2:$B$981,A2) | G2: =SUMIF('화 목록'!$B$2:$B$981,A2,'화 목록'!$F$2:$F$981) | H2: 마드리드 식당·카페에서 하비에르와 알바로가 책·드라마·기사를 두고 나누는 40대 기자 친구의 일상 대화
A3: 2 | B3: A 일상 회화 | C3: 해안 불법 개발 탐사보도 | D3: 8 | E3: 13 | F3: =COUNTIF('화 목록'!$B$2:$B$981,A3) | G3: =SUMIF('화 목록'!$B$2:$B$981,A3,'화 목록'!$F$2:$F$981) | H3: 불법 토지 개발 취재 전략, 제보자 인터뷰, 협박 전화, 국장실 논쟁, 기사 발행
A4: 3 | B4: A 일상 회화 | C4: 신문 기사 읽기 대화 | D4: 14 | E4: 25 | F4: =COUNTIF('화 목록'!$B$2:$B$981,A4) | G4: =SUMIF('화 목록'!$B$2:$B$981,A4,'화 목록'!$F$2:$F$981) | H4: 엘 파이스·WSJ·엘 문도 기사를 읽으며 나누는 국제 정세·사회 이슈 토론
A5: 4 | B5: B 카를로스 사건집 | C5: 카디스 무기 밀매 잠입 | D5: 26 | E5: 52 | F5: =COUNTIF('화 목록'!$B$2:$B$981,A5) | G5: =SUMIF('화 목록'!$B$2:$B$981,A5,'화 목록'!$F$2:$F$981) | H5: CNI 카를로스와 재회, 위장 신분 디에고로 파비안 조직에 잠입, 카르타헤나·베네수엘라(루에다), 하비에르 제거 계획 저지
A6: 5 | B6: B 카를로스 사건집 | C6: 마드리드 경매장과 치무 황금 칼 | D6: 53 | E6: 61 | F6: =COUNTIF('화 목록'!$B$2:$B$981,A6) | G6: =SUMIF('화 목록'!$B$2:$B$981,A6,'화 목록'!$F$2:$F$981) | H6: 위장 신분 다니엘로 유물 밀반출 조직에 잠입, 경매 당일 급습
A7: 6 | B7: B 카를로스 사건집 | C7: 스페인-페루 유물 반환 협상 | D7: 62 | E7: 66 | F7: =COUNTIF('화 목록'!$B$2:$B$981,A7) | G7: =SUMIF('화 목록'!$B$2:$B$981,A7,'화 목록'!$F$2:$F$981) | H7: 치무 칼 반환 이후 포괄적 반환 협상, 키푸 쟁점, 최종 서명
A8: 7 | B8: B 카를로스 사건집 | C8: 대마 합법화와 베르데갈 캐피털 | D8: 67 | E8: 95 | F8: =COUNTIF('화 목록'!$B$2:$B$981,A8) | G8: =SUMIF('화 목록'!$B$2:$B$981,A8,'화 목록'!$F$2:$F$981) | H8: 정치인-투자펀드 금전 연결고리, 마르코 아길라르 신분 잠입, 카스타뇨·아리사 조직 와해
A9: 8 | B9: B 카를로스 사건집 | C9: 라몬 재판과 자금 추적 | D9: 96 | E9: 115 | F9: =COUNTIF('화 목록'!$B$2:$B$981,A9) | G9: =SUMIF('화 목록'!$B$2:$B$981,A9,'화 목록'!$F$2:$F$981) | H9: 정치자금 세탁 추적, 청문회·재판, 증인 수아소 사망, 폭발 사건 | I9: S2-라몬재판-자금추적
A10: 9 | B10: B 카를로스 사건집 | C10: 명품 위조 조직 | D10: 116 | E10: 122 | F10: =COUNTIF('화 목록'!$B$2:$B$981,A10) | G10: =SUMIF('화 목록'!$B$2:$B$981,A10,'화 목록'!$F$2:$F$981) | H10: 톰포드·스페인 명품 위조품 유통망 잠입과 생산 작업장 급습
A11: 10 | B11: B 카를로스 사건집 | C11: 의료관광 클리닉 | D11: 123 | E11: 131 | F11: =COUNTIF('화 목록'!$B$2:$B$981,A11) | G11: =SUMIF('화 목록'!$B$2:$B$981,A11,'화 목록'!$F$2:$F$981) | H11: 가짜 백신·미허가 시술 클리닉 잠입, 시료 분석, 실소유주 추적 | I11: S2-의료관광
A12: 11 | B12: B 카를로스 사건집 | C12: 위기 대응 긴급자금 횡령 | D12: 132 | E12: 138 | F12: =COUNTIF('화 목록'!$B$2:$B$981,A12) | G12: =SUMIF('화 목록'!$B$2:$B$981,A12,'화 목록'!$F$2:$F$981) | H12: 가상 자치도시 푸에르토 알토의 긴급자금 횡령 취재
A13: 12 | B13: B 카를로스 사건집 | C13: 북극 신항로 이중용도 밀수 | D13: 139 | E13: 146 | F13: =COUNTIF('화 목록'!$B$2:$B$981,A13) | G13: =SUMIF('화 목록'!$B$2:$B$981,A13,'화 목록'!$F$2:$F$981) | H13: 노르티아 로히스티카 잠입, 화물 명세서 확보, 선적일 급습 | I13: S2-북극항로
A14: 13 | B14: B 카를로스 사건집 | C14: AI 컴패니언 앱 사기 | D14: 147 | E14: 153 | F14: =COUNTIF('화 목록'!$B$2:$B$981,A14) | G14: =SUMIF('화 목록'!$B$2:$B$981,A14,'화 목록'!$F$2:$F$981) | H14: AI 동반자 앱을 이용한 정서적 포섭 사기와 소비자보호 당국 개입
A15: 14 | B15: B 카를로스 사건집 | C15: 반티아 재난 은폐 검증 | D15: 154 | E15: 159 | F15: =COUNTIF('화 목록'!$B$2:$B$981,A15) | G15: =SUMIF('화 목록'!$B$2:$B$981,A15,'화 목록'!$F$2:$F$981) | H15: 위성사진·영상으로 가상국 반티아의 빙하 붕괴 피해 은폐를 검증하는 보도
A16: 15 | B16: B 카를로스 사건집 | C16: 야마이라 재건 리베이트 | D16: 160 | E16: 165 | F16: =COUNTIF('화 목록'!$B$2:$B$981,A16) | G16: =SUMIF('화 목록'!$B$2:$B$981,A16,'화 목록'!$F$2:$F$981) | H16: 재건 붐 리베이트·자금세탁, 루에다 세계관 확장
A17: 16 | B17: B 카를로스 사건집 | C17: 아이슬란드 어업 쿼터 재협상(1) | D17: 166 | E17: 168 | F17: =COUNTIF('화 목록'!$B$2:$B$981,A17) | G17: =SUMIF('화 목록'!$B$2:$B$981,A17,'화 목록'!$F$2:$F$981) | H17: 스페인-아이슬란드 어획 쿼터 협상 취재
A18: 17 | B18: B 카를로스 사건집 | C18: 가짜 자선단체 기부금 횡령(1) | D18: 169 | E18: 172 | F18: =COUNTIF('화 목록'!$B$2:$B$981,A18) | G18: =SUMIF('화 목록'!$B$2:$B$981,A18,'화 목록'!$F$2:$F$981) | H18: 어린이 의료지원 명목 자선단체의 기부금 횡령 취재
A19: 18 | B19: B 카를로스 사건집 | C19: 푸에르토 수르 이주 긴급자금 | D19: 173 | E19: 179 | F19: =COUNTIF('화 목록'!$B$2:$B$981,A19) | G19: =SUMIF('화 목록'!$B$2:$B$981,A19,'화 목록'!$F$2:$F$981) | H19: 이주 위기 대응 긴급자금의 수상한 집행, 물류업체 위장, 체포와 보도
A20: 19 | B20: B 카를로스 사건집 | C20: 북극 신항로 해운기업 조사 | D20: 180 | E20: 189 | F20: =COUNTIF('화 목록'!$B$2:$B$981,A20) | G20: =SUMIF('화 목록'!$B$2:$B$981,A20,'화 목록'!$F$2:$F$981) | H20: 가상 해운기업 노르티아 나비에라 조사, 재수출 경로 추적, 알헤시라스 항구 압류
A21: 20 | B21: B 카를로스 사건집 | C21: 이모 로사와 AI 동반자 앱 | D21: 190 | E21: 196 | F21: =COUNTIF('화 목록'!$B$2:$B$981,A21) | G21: =SUMIF('화 목록'!$B$2:$B$981,A21,'화 목록'!$F$2:$F$981) | H21: 가족이 피해를 입은 AI 동반자 앱 사건, 가짜 프로필 취재, 보도
A22: 21 | B22: B 카를로스 사건집 | C22: 몬타냐 델 노르테 산사태 은폐 | D22: 197 | E22: 203 | F22: =COUNTIF('화 목록'!$B$2:$B$981,A22) | G22: =SUMIF('화 목록'!$B$2:$B$981,A22,'화 목록'!$F$2:$F$981) | H22: 가상 산악국가의 재해 규모 축소·은폐 검증과 국제 반향
A23: 22 | B23: B 카를로스 사건집 | C23: 카바나스 재건 사업과 컨설턴트 위장 | D23: 204 | E23: 213 | F23: =COUNTIF('화 목록'!$B$2:$B$981,A23) | G23: =SUMIF('화 목록'!$B$2:$B$981,A23,'화 목록'!$F$2:$F$981) | H23: 루에다 잔당 자금이 흘러든 재건 사업, 커미션 지급 추적, 현지 반부패팀 공조
A24: 23 | B24: B 카를로스 사건집 | C24: 아이슬란드 어획 쿼터 협상(2) | D24: 214 | E24: 220 | F24: =COUNTIF('화 목록'!$B$2:$B$981,A24) | G24: =SUMIF('화 목록'!$B$2:$B$981,A24,'화 목록'!$F$2:$F$981) | H24: 비고에서 열린 협상 세션과 협정 서명
A25: 24 | B25: B 카를로스 사건집 | C25: 에스페란사 글로벌 기부금 횡령 | D25: 221 | E25: 228 | F25: =COUNTIF('화 목록'!$B$2:$B$981,A25) | G25: =SUMIF('화 목록'!$B$2:$B$981,A25,'화 목록'!$F$2:$F$981) | H25: 국제 원조 자선단체 횡령 의혹, 자선 갈라 잠입, 법원 명령 집행
... A31: 30 | B31: B 카를로스 사건집 | C31: 농장 이주노동자 강제노동 | D31: 318 | E31: 344 | F31: =COUNTIF('화 목록'!$B$2:$B$981,A31) | G31: =SUMIF('화 목록'!$B$2:$B$981,A31,'화 목록'!$F$2:$F$981) | H31: 마놀로 이바라 신분으로 농장에 잠입, 부상자 병원 이송, 급습, 재판
A32: 31 | B32: B 카를로스 사건집 | C32: 콜롬비아-스페인 마약 조직 잠입 | D32: 345 | E32: 376 | F32: =COUNTIF('화 목록'!$B$2:$B$981,A32) | G32: =SUMIF('화 목록'!$B$2:$B$981,A32,'화 목록'!$F$2:$F$981) | H32: 리고베르토 조직 잠입, 카밀라와의 협력, 탈출, 재판과 판결 | I32: S2-마약조직
A33: 32 | B33: C EU 로비 | C33: EU 브뤼셀 로비 네트워크 | D33: 377 | E33: 460 | F33: =COUNTIF('화 목록'!$B$2:$B$981,A33) | G33: =SUMIF('화 목록'!$B$2:$B$981,A33,'화 목록'!$F$2:$F$981) | H33: 카밀라 위장 접근, 로셀요 체포, 재판·후일담, 제보자 마르턴, 제네바 잠입, 아일랜드·니스 추적, 독일 확대 예고 | I33: S2-EU로비
A34: 33 | B34: D 엘 아르키텍토 추적 | C34: 스페인 중앙은행 공작 | D34: 461 | E34: 484 | F34: =COUNTIF('화 목록'!$B$2:$B$981,A34) | G34: =SUMIF('화 목록'!$B$2:$B$981,A34,'화 목록'!$F$2:$F$981) | H34: 알바로 단독 작전, 토마스 브라보 신분으로 은행 잠입, 이사회 투표일 대응
A35: 34 | B35: D 엘 아르키텍토 추적 | C35: 로셀요의 만찬 회유 | D35: 485 | E35: 494 | F35: =COUNTIF('화 목록'!$B$2:$B$981,A35) | G35: =SUMIF('화 목록'!$B$2:$B$981,A35,'화 목록'!$F$2:$F$981) | H35: 로셀요가 직접 전화해 만찬 제안, 회유·협박, 보안 강화
A36: 35 | B36: D 엘 아르키텍토 추적 | C36: 사프란 원산지 사기 | D36: 495 | E36: 503 | F36: =COUNTIF('화 목록'!$B$2:$B$981,A36) | G36: =SUMIF('화 목록'!$B$2:$B$981,A36,'화 목록'!$F$2:$F$981) | H36: 라만차 사프란 위조 유통업체 취재와 보도
A37: 36 | B37: D 엘 아르키텍토 추적 | C37: 루카와의 재회 | D37: 504 | E37: 508 | F37: =COUNTIF('화 목록'!$B$2:$B$981,A37) | G37: =SUMIF('화 목록'!$B$2:$B$981,A37,'화 목록'!$F$2:$F$981) | H37: 사건 없는 우정 에피소드
A38: 37 | B38: D 엘 아르키텍토 추적 | C38: 무기 밀매와 자금세탁 설계자 로셀요 | D38: 509 | E38: 522 | F38: =COUNTIF('화 목록'!$B$2:$B$981,A38) | G38: =SUMIF('화 목록'!$B$2:$B$981,A38,'화 목록'!$F$2:$F$981) | H38: 브루노 베테르그렌 신분 잠입, 발렌시아·카르타헤나 항구 급습
A39: 38 | B39: D 엘 아르키텍토 추적 | C39: 칸타브리아 저택 취재와 출판 계약 | D39: 523 | E39: 548 | F39: =COUNTIF('화 목록'!$B$2:$B$981,A39) | G39: =SUMIF('화 목록'!$B$2:$B$981,A39,'화 목록'!$F$2:$F$981) | H39: 로셀요 연결 부동산 단독 취재, 도밍고·안셀모, 출판 계약
A40: 39 | B40: E 빅토르 안전가옥 세션 | C40: 빅토르의 접선과 망명 | D40: 549 | E40: 558 | F40: =COUNTIF('화 목록'!$B$2:$B$981,A40) | G40: =SUMIF('화 목록'!$B$2:$B$981,A40,'화 목록'!$F$2:$F$981) | H40: 해외 정보기관 요원 빅토르의 암호화 메시지, 정황 검증, CNI 보호
A41: 40 | B41: E 빅토르 안전가옥 세션 | C41: 신빙성 검증: 임플란트와 산타클로스 작전 | D41: 559 | E41: 585 | F41: =COUNTIF('화 목록'!$B$2:$B$981,A41) | G41: =SUMIF('화 목록'!$B$2:$B$981,A41,'화 목록'!$F$2:$F$981) | H41: 종결 작전부터 검증, 하드웨어 임플란트, 산타클로스 작전
A42: 41 | B42: E 빅토르 안전가옥 세션 | C42: 아담과 이브 작전 | D42: 586 | E42: 596 | F42: =COUNTIF('화 목록'!$B$2:$B$981,A42) | G42: =SUMIF('화 목록'!$B$2:$B$981,A42,'화 목록'!$F$2:$F$981) | H42: 위장 신원 구축, 요원 훈련과 이탈 과정
A43: 42 | B43: E 빅토르 안전가옥 세션 | C43: 알시온 작전: 로셀요의 기원 | D43: 597 | E43: 613 | F43: =COUNTIF('화 목록'!$B$2:$B$981,A43) | G43: =SUMIF('화 목록'!$B$2:$B$981,A43,'화 목록'!$F$2:$F$981) | H43: 로셀요의 기원과 후보 6명의 운명
A44: 43 | B44: E 빅토르 안전가옥 세션 | C44: 엘 아르키텍토 프로그램 | D44: 614 | E44: 652 | F44: =COUNTIF('화 목록'!$B$2:$B$981,A44) | G44: =SUMIF('화 목록'!$B$2:$B$981,A44,'화 목록'!$F$2:$F$981) | H44: 후계자 양성 프로그램의 구조와 실패, 로셀요 인물 분석
A45: 44 | B45: E 빅토르 안전가옥 세션 | C45: 크리스탈·코리엔테 수르·영원의 도서관 | D45: 653 | E45: 656 | F45: =COUNTIF('화 목록'!$B$2:$B$981,A45) | G45: =SUMIF('화 목록'!$B$2:$B$981,A45,'화 목록'!$F$2:$F$981) | H45: 활성 작전과 빅토르의 옛 기관이 직접 설계한 작전들
...

Sheet 화 목록
A1: 화 번호 | B1: 부작 번호 | C1: 부작 제목 | D1: 파트 | E1: 문서 내 문단 위치 | F1: 대화 줄 수(근사) | G1: 상황 설명(원문 발췌)
A2: 1 | B2: 1 | C2: =INDEX('부작 목록'!$C$2:$C$66,B2) | D2: A 일상 회화 | E2: 0 | F2: 55 | G2: 마드리드 중심가, 토요일 점심시간의 활기찬 식당입니다. 40대 마드리드 토박이 기자 친구인 하 비에르(Javier)와 알바로(Álvaro)가 테라스 좌석에 앉아 맥주(Caña)를 곁들인 식사를 하며 나누는 대화입니다.
A3: 2 | B3: 1 | C3: =INDEX('부작 목록'!$C$2:$C$66,B3) | D3: A 일상 회화 | E3: 59 | F3: 26 | G3: 일주일 후, 다시 마드리드 시내의 같은 식당에서 만난 하비에르와 알바로의 대화입니다. 이번에 는 지난 한 주간의 구체적인 업무 성과와 개인적인 일들에 대해 조금 더 깊은 대화를 나눕니다.
A4: 3 | B4: 1 | C4: =INDEX('부작 목록'!$C$2:$C$66,B4) | D4: A 일상 회화 | E4: 88 | F4: 46 | G4: 이 대화문은 리 차일드(Lee Child)의 소설 『Zona Peligrosa(영제: Killing Floor)』를 읽은 두 명의 40대 기자, 하비에르와 알바로가 그 내용과 문학적 장치에 대해 깊이 있게 토론하는 상황입니 다. 요청하신 대로 접속법, 대과거, 조건법 등을 집중적으로 배치했습니다.
A5: 4 | B5: 1 | C5: =INDEX('부작 목록'!$C$2:$C$66,B5) | D5: A 일상 회화 | E5: 139 | F5: 28 | G5: 이번에는 아마존 프라임의 드라마 『리처(Reacher)』 시즌 1을 본 후, 하비에르와 알바로가 그 각색의 완성도와 원작과의 차이점에 대해 대화를 나누는 상황입니다. 드라마에 대한 비평인 만 큼, 앞선 대화보다 더 복잡한 가정과 분석이 포함되어 있습니다.
A6: 5 | B6: 1 | C6: =INDEX('부작 목록'!$C$2:$C$66,B6) | D6: A 일상 회화 | E6: 171 | F6: 23 | G6: 하비에르와 알바로가 이번에는 드라마 『리처(Reacher)』 시즌 3를 시청한 후, 한층 더 비평적인 시각으로 나누는 대화입니다. 시즌을 거듭하며 익숙해진 팬들로서, 원작의 정체성과 시리즈의 방향성에 대해 보다 깊은 분석을 담았습니다.
A7: 6 | B7: 1 | C7: =INDEX('부작 목록'!$C$2:$C$66,B7) | D7: A 일상 회화 | E7: 197 | F7: 21 | G7: 시즌 3의 강렬하고도 씁쓸한 엔딩 장면, 그리고 그 여운을 극대화했던 Mondo Cozmo의 음악 에 대해 하비에르와 알바로가 깊은 감상을 나누는 대화문입니다.
A8: 7 | B8: 1 | C8: =INDEX('부작 목록'!$C$2:$C$66,B8) | D8: A 일상 회화 | E8: 221 | F8: 22 | G8: 지난주 각자 취재한 기사(하비에르는 경제 분야, 알바로는 정치/사회 분야)에 대해 마드리드의 한 식당에서 식사를 하며 서로의 취재 과정과 결과를 비판적으로 공유하는 상황입니다. 이번 대 화문은 전문적인 견해를 나누는 만큼 접속법과 조건법이 밀도 있게 사용되었습니다.
A9: 8 | B9: 2 | C9: =INDEX('부작 목록'!$C$2:$C$66,B9) | D9: A 일상 회화 | E9: 247 | F9: 18 | G9: 다음 주부터 시작될 '해안 지역의 불법 토지 개발 및 환경 파괴'라는 묵직한 탐사보도 주제를 놓고, 두 기자가 구체적인 취재 전략과 위험 요소를 논의하는 상황입니다. 이번 대화문에서는 미래에 대한 계획과 가정(가정법/조건법), 그리고 상대방의 의견을 이끌어내는 접속법이 집중적 으로 사용되었습니다.
A10: 9 | B10: 2 | C10: =INDEX('부작 목록'!$C$2:$C$66,B10) | D10: A 일상 회화 | E10: 268 | F10: 18 | G10: 알바로(Álvaro)가 불법 건축과 환경 파괴의 중심에 있는 익명의 제보자(혹은 내부 고발자)를 만 나 인터뷰하는 상황입니다. 긴장감이 감도는 취재 현장의 분위기를 살려, 접속법을 이용한 신뢰 확보와 조건법을 통한 가설적 상황 제시를 중심으로 구성했습니다.
A11: 10 | B11: 2 | C11: =INDEX('부작 목록'!$C$2:$C$66,B11) | D11: A 일상 회화 | E11: 290 | F11: 15 | G11: 알바로(Álvaro)가 데스크(상사)에게 취재한 내용과 확보한 증거물을 보고하며, 향후 보도 방향과 법적 리스크에 대해 논의하는 긴장감 넘치는 상황입니다. 상사와의 대화이므로 격식 있는 어조 와 접속법을 활용한 정중한 제안, 그리고 객관적 분석을 위한 직설법이 조화를 이룹니다.
A12: 11 | B12: 2 | C12: =INDEX('부작 목록'!$C$2:$C$66,B12) | D12: A 일상 회화 | E12: 308 | F12: 14 | G12: 알바로가 퇴근길 혹은 집에 돌아왔을 때, 보도 준비 중인 불법 토지 개발 건을 중단하라는 익명 의 협박 전화를 받는 상황입니다. 상대방은 알바로의 신상과 취재 내용을 상세히 알고 있다는 점을 강조하며 심리적 압박을 가합니다.
A13: 12 | B13: 2 | C13: =INDEX('부작 목록'!$C$2:$C$66,B13) | D13: A 일상 회화 | E13: 325 | F13: 24 | G13: 이 상황은 협박 전화 이후, 알바로가 국장실에서 안전 문제와 보도 가치를 두고 벌이는 치열한 논쟁, 그리고 결국 진실을 위해 기사를 송고하기로 합의하는 긴박한 순간입니다.
... A981: 980 | B981: 65 | C981: =INDEX('부작 목록'!$C$2:$C$66,B981) | D981: E 빅토르 안전가옥 세션 | E981: 16674 | F981: 19 | G981: 며칠 후. 알바로가 정기 면회 중 로셀요에게 라이프치히 드론 공격을 EU가 '국가 후원 테러리즘 '으로 규정한 기사를 화제로 꺼냅니다.

Sheet 설명
A1: 알바로 이야기 첨부 문서(6e765f55-…5.docx) 부작·화 구분표
A3: 구분 기준
A4: - 화: 문서에서 장면마다 붙은 한국어 상황 설명 문단 1개 = 1화 (총 980화).
A5: - 부작: 상황 설명의 "새로운 작전/취재/세션", "신규 아크", 사건 마무리 문구와 사건 주제가 바뀌는 지점으로 묶음 (총 65부작).
A6: - 파트: 부작을 크게 묶은 5개 분류 (A 일상 회화, B 카를로스 사건집, C EU 로비, D 엘 아르키텍토 추적, E 빅토르 안전가옥 세션).
A7: - 부작 제목·핵심 내용은 상황 설명을 읽고 직접 붙인 것이며, 문서 원문에 있는 제목이 아닙니다.
A8: - 부작 경계(시작 화/끝 화)는 파란색 입력값입니다. 고치면 화 수·대화 줄 수 등은 화 목록과 연동되지만, 화 목록의 부작 번호는 자동 갱신되지 않습니다.
A10: 한계
A11: - 화 목록의 상황 설명은 원문 발췌이며, 원문 줄바꿈 때문에 한글 사이에 공백이 끼어 있는 곳이 있습니다.
A12: - 대화 줄 수는 상황 설명 다음부터 다음 상황 설명 전까지의 문단 수라서 근사값입니다(줄바꿈된 대사는 여러 줄로 셈).
A13: - 일부 화는 상황 설명이 한두 문장뿐이라 같은 장면이 둘로 나뉘었을 수 있습니다.
A14: - "저장소 해설 폴더"는 장면 수가 일치하는 저장소 폴더(S2-…)를 표시한 것입니다. 95~459화 구간과 대응됩니다.
